Workbook
Name DATUMS: 'Tijd 2000'!$A$2:$A$40
Name TIJD: 'Tijd 2000'!$R$2:$R$40
Name TIJDEN: 'Tijd 2000'!$A$2:$A$40

Sheet Reeksen
A1: DatumTijd | B1: AFSTAND | C1: TIJD | D1: Gemid / km | E1: AVG | F1: MAX | G1: CAL | I1: km/u | J1: 10km | K1: 21.1km | L1: 10 EM | M1: 42.2km | N1: c/km | O1: c/h
A2: 36926.769 | B2: 6.35 | C2: 0.019016204 | D2: =IF(B2>0,C2/B2,"") -> 0.0029946777 | E2: 182 | F2: 198 | I2: =1/(D2*24) -> 13.913573 | J2: =1/((178/(ConditieGetal!$B$2*(E2/(I2*ConditieGetal!$B$2))))*24)*10 -> 0.030619739
A3: 36929.88 | B3: 6.35 | C3: 0.01849537 | D3: =IF(B3>0,C3/B3,"") -> 0.0029126568 | E3: 180 | F3: 195 | I3: =1/(D3*24) -> 14.305382 | J3: =1/((178/(ConditieGetal!$B$2*(E3/(I3*ConditieGetal!$B$2))))*24)*10 -> 0.029453832
A4: 36937.474 | B4: 6.35 | C4: 0.018738426 | D4: =IF(B4>0,C4/B4,"") -> 0.0029509332 | E4: 178 | F4: 195 | I4: =1/(D4*24) -> 14.119827 | J4: =1/((178/(ConditieGetal!$B$2*(E4/(I4*ConditieGetal!$B$2))))*24)*10 -> 0.029509332
A5: 36939.443 | B5: 10.26 | C5: 0.035243056 | D5: =IF(B5>0,C5/B5,"") -> 0.0034349957 | E5: 175 | F5: 188 | I5: =1/(D5*24) -> 12.130049 | J5: =1/((178/(ConditieGetal!$B$2*(E5/(I5*ConditieGetal!$B$2))))*24)*10 -> 0.033771025
A6: 36940.71 | B6: 10.26 | C6: 0.032650463 | D6: =IF(B6>0,C6/B6,"") -> 0.0031823063 | E6: 172 | F6: 177 | I6: =1/(D6*24) -> 13.093229 | J6: =1/((178/(ConditieGetal!$B$2*(E6/(I6*ConditieGetal!$B$2))))*24)*10 -> 0.030750376
A7: 36944.874 | B7: 6.35 | C7: 0.017824074 | D7: =IF(B7>0,C7/B7,"") -> 0.0028069408 | E7: 176 | F7: 194 | I7: =1/(D7*24) -> 14.844156 | J7: =1/((178/(ConditieGetal!$B$2*(E7/(I7*ConditieGetal!$B$2))))*24)*10 -> 0.027754021
A8: 36950.876 | B8: 10.26 | C8: 0.031728009 | D8: =IF(B8>0,C8/B8,"") -> 0.0030923986 | E8: 168 | F8: 181 | I8: =1/(D8*24) -> 13.473899 | J8: =1/((178/(ConditieGetal!$B$2*(E8/(I8*ConditieGetal!$B$2))))*24)*10 -> 0.029186683
A9: 36953.707 | B9: 12.7 | C9: 0.042534722 | D9: =IF(B9>0,C9/B9,"") -> 0.0033491907 | E9: 162 | F9: 186 | I9: =1/(D9*24) -> 12.440816 | J9: =1/((178/(ConditieGetal!$B$2*(E9/(I9*ConditieGetal!$B$2))))*24)*10 -> 0.030481399
A10: 36955.869 | B10: 10.26 | C10: 0.029299769 | D10: =IF(B10>0,C10/B10,"") -> 0.0028557279 | E10: 172 | F10: 188 | I10: =1/(D10*24) -> 14.590559 | J10: =1/((178/(ConditieGetal!$B$2*(E10/(I10*ConditieGetal!$B$2))))*24)*10 -> 0.027594674
A11: 36961.44 | B11: 12.7 | C11: 0.042106481 | D11: =IF(B11>0,C11/B11,"") -> 0.003315471 | E11: 163 | F11: 173 | I11: =1/(D11*24) -> 12.567345 | J11: =1/((178/(ConditieGetal!$B$2*(E11/(I11*ConditieGetal!$B$2))))*24)*10 -> 0.030360774
A12: 36963.872 | B12: 12.7 | C12: 0.036969907 | D12: =IF(B12>0,C12/B12,"") -> 0.0029110163 | E12: 170 | F12: 184 | I12: =1/(D12*24) -> 14.313443 | J12: =1/((178/(ConditieGetal!$B$2*(E12/(I12*ConditieGetal!$B$2))))*24)*10 -> 0.027801841
A13: 36965.724 | B13: 10.26 | C13: 0.028225694 | D13: =IF(B13>0,C13/B13,"") -> 0.0027510423 | E13: 175 | F13: 185 | I13: =1/(D13*24) -> 15.145774 | J13: =1/((178/(ConditieGetal!$B$2*(E13/(I13*ConditieGetal!$B$2))))*24)*10 -> 0.027046765
... A20: 37030.434 | B20: 12.7 | C20: 0.041863426 | D20: =IF(B20>0,C20/B20,"") -> 0.0032963328 | E20: 162 | F20: 176 | I20: =1/(D20*24) -> 12.64031 | J20: =1/((178/(ConditieGetal!$B$2*(E20/(I20*ConditieGetal!$B$2))))*24)*10 -> 0.030000332
A21: 37031.475 | B21: 10.26 | C21: 0.03041088 | D21: =IF(B21>0,C21/B21,"") -> 0.0029640234 | E21: 167 | I21: =1/(D21*24) -> 14.057469 | J21: =1/((178/(ConditieGetal!$B$2*(E21/(I21*ConditieGetal!$B$2))))*24)*10 -> 0.027808534
A22: 37032.873 | B22: 12.7 | C22: 0.036679398 | D22: =IF(B22>0,C22/B22,"") -> 0.0028881416 | E22: 164 | I22: =1/(D22*24) -> 14.426809 | J22: =1/((178/(ConditieGetal!$B$2*(E22/(I22*ConditieGetal!$B$2))))*24)*10 -> 0.026609844
A23: 37034.772 | B23: 5 | C23: 0.013234954 | D23: =IF(B23>0,C23/B23,"") -> 0.0026469907 | E23: 172 | F23: 182 | I23: =1/(D23*24) -> 15.741146 | J23: =1/((178/(ConditieGetal!$B$2*(E23/(I23*ConditieGetal!$B$2))))*24)*10 -> 0.025577663
A24: 37037.735 | B24: 10.26 | C24: 0.02843287 | D24: =IF(B24>0,C24/B24,"") -> 0.0027712349 | E24: 168 | F24: 180 | I24: =1/(D24*24) -> 15.035415 | J24: =1/((178/(ConditieGetal!$B$2*(E24/(I24*ConditieGetal!$B$2))))*24)*10 -> 0.026155476
A25: 37038.865 | B25: 6.35 | C25: 0.017574074 | D25: =IF(B25>0,C25/B25,"") -> 0.0027675707 | E25: 162 | F25: 169 | I25: =1/(D25*24) -> 15.055321 | J25: =1/((178/(ConditieGetal!$B$2*(E25/(I25*ConditieGetal!$B$2))))*24)*10 -> 0.025188003
A26: 37040.88 | B26: 12.7 | C26: 0.034924769 | D26: =IF(B26>0,C26/B26,"") -> 0.0027499818 | E26: 167 | F26: 180 | I26: =1/(D26*24) -> 15.151616 | J26: =1/((178/(ConditieGetal!$B$2*(E26/(I26*ConditieGetal!$B$2))))*24)*10 -> 0.025800391
A27: 37042.795 | B27: 1 | C27: 0.002056713 | D27: =IF(B27>0,C27/B27,"") -> 0.002056713 | E27: 168 | F27: 185 | I27: =1/(D27*24) -> 20.258863 | J27: =1/((178/(ConditieGetal!$B$2*(E27/(I27*ConditieGetal!$B$2))))*24)*10 -> 0.019411673
A28: 37043.815 | B28: =2*6.47 -> 12.94 | C28: 0.034060185 | D28: =IF(B28>0,C28/B28,"") -> 0.0026321627 | E28: 177 | F28: 189 | H28: Jogging Schoorhei | I28: =1/(D28*24) -> 15.829822 | J28: =1/((178/(ConditieGetal!$B$2*(E28/(I28*ConditieGetal!$B$2))))*24)*10 -> 0.026173753
A29: 37049.772 | B29: 6.35 | C29: 0.019623843 | D29: =IF(B29>0,C29/B29,"") -> 0.0030903689 | E29: 150 | F29: 156 | I29: =1/(D29*24) -> 13.482748 | J29: =1/((178/(ConditieGetal!$B$2*(E29/(I29*ConditieGetal!$B$2))))*24)*10 -> 0.026042435
A30: 37050.713 | B30: 10.26 | C30: 0.032667824 | D30: =IF(B30>0,C30/B30,"") -> 0.0031839984 | E30: 151 | F30: 156 | I30: =1/(D30*24) -> 13.086271 | J30: =1/((178/(ConditieGetal!$B$2*(E30/(I30*ConditieGetal!$B$2))))*24)*10 -> 0.027010324
A31: 37054.751 | B31: 6.35 | C31: 0.020969907 | D31: =IF(B31>0,C31/B31,"") -> 0.0033023476 | E31: 150 | F31: 156 | I31: =1/(D31*24) -> 12.617287 | J31: =1/((178/(ConditieGetal!$B$2*(E31/(I31*ConditieGetal!$B$2))))*24)*10 -> 0.027828772
A32: 37058.769 | B32: 9 | C32: 0.023905093 | D32: =IF(B32>0,C32/B32,"") -> 0.0026561214 | E32: 180 | F32: 194 | H32: Jogging Wezel | I32: =1/(D32*24) -> 15.687034 | J32: =1/((178/(ConditieGetal!$B$2*(E32/(I32*ConditieGetal!$B$2))))*24)*10 -> 0.026859655
A33: 37145.472 | B33: 6.35 | C33: 0.023119213 | D33: =IF(B33>0,C33/B33,"") -> 0.0036408209 | E33: 166 | F33: 189 | I33: =1/(D33*24) -> 11.444305 | J33: =1/((178/(ConditieGetal!$B$2*(E33/(I33*ConditieGetal!$B$2))))*24)*10 -> 0.033953723
A34: 37158.785 | B34: 6.35 | C34: 0.022071759 | D34: =IF(B34>0,C34/B34,"") -> 0.0034758676 | E34: 158 | F34: 181 | I34: =1/(D34*24) -> 11.987415 | J34: =1/((178/(ConditieGetal!$B$2*(E34/(I34*ConditieGetal!$B$2))))*24)*10 -> 0.030853207
A35: 37166.879 | B35: 6.35 | C35: 0.02225 | D35: =IF(B35>0,C35/B35,"") -> 0.003503937 | E35: 161 | F35: 197 | I35: =1/(D35*24) -> 11.891386 | J35: =1/((178/(ConditieGetal!$B$2*(E35/(I35*ConditieGetal!$B$2))))*24)*10 -> 0.031692913
A36: 37170.683 | B36: 6.35 | C36: 0.022798611 | D36: =IF(B36>0,C36/B36,"") -> 0.0035903325 | E36: 161 | F36: 202 | I36: =1/(D36*24) -> 11.605239 | J36: =1/((178/(ConditieGetal!$B$2*(E36/(I36*ConditieGetal!$B$2))))*24)*10 -> 0.032474355
A37: 37171.45 | B37: 10.26 | C37: 0.041979167 | D37: =IF(B37>0,C37/B37,"") -> 0.0040915367 | E37: 157 | F37: 205 | I37: =1/(D37*24) -> 10.183623 | J37: =1/((178/(ConditieGetal!$B$2*(E37/(I37*ConditieGetal!$B$2))))*24)*10 -> 0.036088273
A38: 37174.878 | B38: 6.35 | C38: 0.022693287 | D38: =IF(B38>0,C38/B38,"") -> 0.003573746 | E38: 161 | F38: 196 | I38: =1/(D38*24) -> 11.659101 | J38: =1/((178/(ConditieGetal!$B$2*(E38/(I38*ConditieGetal!$B$2))))*24)*10 -> 0.032324332
A39: 37176.884 | B39: 6.35 | C39: 0.022416667 | D39: =IF(B39>0,C39/B39,"") -> 0.0035301837 | E39: 162 | F39: 205 | I39: =1/(D39*24) -> 11.802974 | J39: =1/((178/(ConditieGetal!$B$2*(E39/(I39*ConditieGetal!$B$2))))*24)*10 -> 0.032128638
A40: 37177.749 | B40: 6.35 | C40: 0.01919213 | D40: =IF(B40>0,C40/B40,"") -> 0.0030223826 | E40: 173 | F40: 192 | I40: =1/(D40*24) -> 13.786033 | J40: =1/((178/(ConditieGetal!$B$2*(E40/(I40*ConditieGetal!$B$2))))*24)*10 -> 0.029374842
A41: 37186.729 | B41: 6.35 | C41: 0.020978009 | D41: =IF(B41>0,C41/B41,"") -> 0.0033036235 | E41: 174 | F41: 198 | I41: =1/(D41*24) -> 12.612414 | J41: =1/((178/(ConditieGetal!$B$2*(E41/(I41*ConditieGetal!$B$2))))*24)*10 -> 0.032293848
A42: 37193.881 | B42: 10.26 | C42: 0.035783565 | D42: =IF(B42>0,C42/B42,"") -> 0.0034876769 | E42: 159 | F42: 198 | I42: =1/(D42*24) -> 11.946825 | J42: =1/((178/(ConditieGetal!$B$2*(E42/(I42*ConditieGetal!$B$2))))*24)*10 -> 0.031153968
A43: 37195.745 | B43: 12.7 | C43: 0.046828704 | D43: =IF(B43>0,C43/B43,"") -> 0.0036872995 | E43: 158 | F43: 185 | I43: =1/(D43*24) -> 11.300049 | J43: =1/((178/(ConditieGetal!$B$2*(E43/(I43*ConditieGetal!$B$2))))*24)*10 -> 0.032729962
A44: 37196.817 | B44: 10.26 | C44: 0.039328704 | D44: =IF(B44>0,C44/B44,"") -> 0.003833207 | E44: 150 | F44: 197 | I44: =1/(D44*24) -> 10.869923 | J44: =1/((178/(ConditieGetal!$B$2*(E44/(I44*ConditieGetal!$B$2))))*24)*10 -> 0.032302306
A45: 37281.713 | B45: 10.26 | C45: 0.033105324 | D45: =IF(B45>0,C45/B45,"") -> 0.0032266398 | E45: 162 | F45: 187 | I45: =1/(D45*24) -> 12.913331 | J45: =1/((178/(ConditieGetal!$B$2*(E45/(I45*ConditieGetal!$B$2))))*24)*10 -> 0.029366047
A46: 37282.564 | B46: =10.26+6.35 -> 16.61 | C46: 0.063333333 | D46: =IF(B46>0,C46/B46,"") -> 0.0038129641 | E46: 153 | F46: 171 | I46: =1/(D46*24) -> 10.927632 | J46: =1/((178/(ConditieGetal!$B$2*(E46/(I46*ConditieGetal!$B$2))))*24)*10 -> 0.032774354
...

Sheet Garmin
A1: Naam activiteit | B1: Type activiteit | C1: Start | D1: Tijd | E1: Afstand | F1: Winst hoogte | G1: Gem. snelheid(Gem. tempo) | H1: Max. snelheid(Beste tempo) | I1: Gem. HS | J1: Max. HS | K1: Calorieën | L1: Totaal slagen | M1: Gemiddelde slagen | N1: Minmum slagen | O1: Gemiddelde SWOLF | P1: Beste SWOLF | Q1: Beste efficiency | R1: Training Effect | S1: Gemiddelde efficiency
C3: Naamloos | D3: Hardlopen | E3: zo, 26 feb 2012 15:18 | F3: 0.31527778 | G3: 0.46 | H3: 5 | I3: 0.68611111 | J3: :22 | K3: 146 | L3: 174 | M3: 84 | N3: -- | O3: -- | P3: -- | Q3: -- | R3: -- | S3: -- | T3: 2.1 | U3: --
C4: Naamloos | D4: Hardlopen | E4: zo, 26 feb 2012 15:15 | F4: 0.072222222 | G4: 0 | H4: -- | I4: --:-- | J4: -- | K4: 155 | L4: 164 | M4: 22 | N4: -- | O4: -- | P4: -- | Q4: -- | R4: -- | S4: -- | T4: 1.4 | U4: --
C5: Naamloos | D5: Hardlopen | E5: zo, 26 feb 2012 15:00 | F5: 0.46527778 | G5: 0 | H5: -- | I5: --:-- | J5: -- | K5: 139 | L5: 150 | M5: 118 | N5: -- | O5: -- | P5: -- | Q5: -- | R5: -- | S5: -- | T5: 2 | U5: --
C6: Naamloos | D6: Hardlopen | E6: za, 25 feb 2012 15:36 | F6: 2.3611111 | G6: 11.33 | H6: 62 | I6: 0.20833333 | J6: 0.076388889 | K6: 155 | L6: 176 | M6: 613 | N6: -- | O6: -- | P6: -- | Q6: -- | R6: -- | S6: -- | T6: 4.3 | U6: --
C7: Naamloos | D7: Hardlopen | E7: di, 21 feb 2012 18:31 | F7: 0.049826389 | G7: 11.56 | H7: 33 | I7: 0.25833333 | J7: :40 | K7: 147 | L7: 185 | M7: 735 | N7: -- | O7: -- | P7: -- | Q7: -- | R7: -- | S7: -- | T7: 3.7 | U7: --
C8: Naamloos | D8: Hardlopen | E8: za, 18 feb 2012 18:04 | F8: 0.43194444 | G8: 1.9 | H8: 6 | I8: 0.22777778 | J8: 0.18472222 | K8: 161 | L8: 169 | M8: 133 | N8: -- | O8: -- | P8: -- | Q8: -- | R8: -- | S8: -- | T8: 2.7 | U8: --
C9: Naamloos | D9: Hardlopen | E9: za, 18 feb 2012 17:25 | F9: 1.5652778 | G9: 7.67 | H9: 45 | I9: 0.20416667 | J9: 0.15416667 | K9: 166 | L9: 185 | M9: 480 | N9: -- | O9: -- | P9: -- | Q9: -- | R9: -- | S9: -- | T9: 4.5 | U9: --
C10: Naamloos | D10: Hardlopen | E10: za, 18 feb 2012 17:18 | F10: 0.17986111 | G10: 0.67 | H10: 8 | I10: 0.26666667 | J10: 0.2125 | K10: 126 | L10: 141 | M10: 35 | N10: -- | O10: -- | P10: -- | Q10: -- | R10: -- | S10: -- | T10: 1.3 | U10: --
C11: Naamloos | D11: Hardlopen | E11: wo, 15 feb 2012 20:32 | F11: 0.089583333 | G11: 0.64 | H11: 0 | I11: 0.14027778 | J11: 0.12222222 | K11: 186 | L11: 195 | M11: 32 | N11: -- | O11: -- | P11: -- | Q11: -- | R11: -- | S11: -- | T11: 2.1 | U11: --
C12: Naamloos | D12: Hardlopen | E12: wo, 15 feb 2012 20:20 | F12: 0.28611111 | G12: 1.38 | H12: 2 | I12: 0.20694444 | J12: 0.11527778 | K12: 176 | L12: 201 | M12: 95 | N12: -- | O12: -- | P12: -- | Q12: -- | R12: -- | S12: -- | T12: 3.2 | U12: --
C13: Naamloos | D13: Hardlopen | E13: wo, 15 feb 2012 20:10 | F13: 0.36805556 | G13: 1.39 | H13: 2 | I13: 0.26527778 | J13: 0.20138889 | K13: 178 | L13: 188 | M13: 124 | N13: -- | O13: -- | P13: -- | Q13: -- | R13: -- | S13: -- | T13: 3 | U13: --
C14: Naamloos | D14: Hardlopen | E14: wo, 15 feb 2012 20:02 | F14: 0.27569444 | G14: 1.7 | H14: 0 | I14: 0.1625 | J14: 0.14583333 | K14: 198 | L14: 201 | M14: 107 | N14: -- | O14: -- | P14: -- | Q14: -- | R14: -- | S14: -- | T14: 3.3 | U14: --
C15: Naamloos | D15: Hardlopen | E15: wo, 15 feb 2012 20:00 | F15: 0.05 | G15: 0.22 | H15: 0 | I15: 0.22638889 | J15: 0.15 | K15: 179 | L15: 190 | M15: 3 | N15: -- | O15: -- | P15: -- | Q15: -- | R15: -- | S15: -- | T15: 1.6 | U15: --
C16: Naamloos | D16: Hardlopen | E16: wo, 15 feb 2012 18:57 | F16: 0.042962963 | G16: 7.68 | H16: 29 | I16: 0.33611111 | J16: 0.14722222 | K16: 152 | L16: 195 | M16: 616 | N16: -- | O16: -- | P16: -- | Q16: -- | R16: -- | S16: -- | T16: 5 | U16: --
C17: Naamloos | D17: Hardlopen | E17: wo, 15 feb 2012 18:46 | F17: 0.42916667 | G17: 1.86 | H17: 8 | I17: 0.23055556 | J17: :44 | K17: 168 | L17: 182 | M17: 137 | N17: -- | O17: -- | P17: -- | Q17: -- | R17: -- | S17: -- | T17: 2.8 | U17: --
C18: Naamloos | D18: Hardlopen | E18: wo, 15 feb 2012 18:31 | F18: 0.38819444 | G18: 1.52 | H18: 4 | I18: 0.25555556 | J18: 0.1625 | K18: 151 | L18: 173 | M18: 88 | N18: -- | O18: -- | P18: -- | Q18: -- | R18: -- | S18: -- | T18: 2.1 | U18: --
C19: Naamloos | D19: Hardlopen | E19: wo, 15 feb 2012 18:27 | F19: :19 | G19: 0 | H19: -- | I19: --:-- | J19: -- | K19: 88 | L19: 90 | M19: 0 | N19: -- | O19: -- | P19: -- | Q19: -- | R19: -- | S19: -- | T19: 1 | U19: --
C20: Naamloos | D20: Hardlopen | E20: di, 14 feb 2012 21:08 | F20: 0.15625 | G20: 0 | H20: -- | I20: --:-- | J20: -- | K20: -- | L20: -- | M20: 0 | N20: -- | O20: -- | P20: -- | Q20: -- | R20: -- | S20: -- | T20: -- | U20: --
C21: Naamloos | D21: Hardlopen | E21: di, 14 feb 2012 20:54 | F21: 0.20833333 | G21: 0 | H21: -- | I21: --:-- | J21: -- | K21: -- | L21: -- | M21: 0 | N21: -- | O21: -- | P21: -- | Q21: -- | R21: -- | S21: -- | T21: -- | U21: --
C22: Naamloos | D22: Hardlopen | E22: di, 7 feb 2012 18:35 | F22: 2.3111111 | G22: 9.21 | H22: 22 | I22: 0.25069444 | J22: :50 | K22: 166 | L22: 206 | M22: 753 | N22: -- | O22: -- | P22: -- | Q22: -- | R22: -- | S22: -- | T22: 5 | U22: --

Sheet Kilometers
A1: DatumTijd | B1: Kilometer | C1: Tijden | D1: GemHartSlag | E1: km/u | F1: min/km
A3: 36926.769 | B3: 1 | C3: 0.0029050926 | D3: 165 | E3: =(B3-0)/((C3-0)*24) -> 14.342629 | F3: =1/(E3*24) -> 0.0029050926
A4: 36926.769 | B4: 2 | C4: 0.0058101852 | D4: 180 | E4: =(B4-B3)/((C4-C3)*24) -> 14.342629 | F4: =1/(E4*24) -> 0.0029050926
A5: 36926.769 | B5: 3 | C5: 0.0088541667 | D5: 183 | E5: =(B5-B4)/((C5-C4)*24) -> 13.688213 | F5: =1/(E5*24) -> 0.0030439815
A6: 36926.769 | B6: 4 | C6: 0.011944444 | D6: 184 | E6: =(B6-B5)/((C6-C5)*24) -> 13.483146 | F6: =1/(E6*24) -> 0.0030902778
A7: 36926.769 | B7: 5 | C7: 0.015081019 | D7: 187 | E7: =(B7-B6)/((C7-C6)*24) -> 13.284133 | F7: =1/(E7*24) -> 0.0031365741
A8: 36926.769 | B8: 6 | C8: 0.018078704 | D8: 190 | E8: =(B8-B7)/((C8-C7)*24) -> 13.899614 | F8: =1/(E8*24) -> 0.0029976852
A9: 36929.88 | B9: 1 | C9: 0.0030555556 | D9: 154 | E9: =(B9-B8)/((C9-C8)*24) -> 13.867488 | F9: =1/(E9*24) -> 0.0030046296
A10: 36929.88 | B10: 2 | C10: 0.0058796296 | D10: 176 | E10: =(B10-B9)/((C10-C9)*24) -> 14.754098 | F10: =1/(E10*24) -> 0.0028240741
A11: 36929.88 | B11: 3 | C11: 0.0088541667 | D11: 182 | E11: =(B11-B10)/((C11-C10)*24) -> 14.007782 | F11: =1/(E11*24) -> 0.002974537
A12: 36929.88 | B12: 4 | C12: 0.011793981 | D12: 184 | E12: =(B12-B11)/((C12-C11)*24) -> 14.173228 | F12: =1/(E12*24) -> 0.0029398148
A13: 36929.88 | B13: 5 | C13: 0.014733796 | D13: 188 | E13: =(B13-B12)/((C13-C12)*24) -> 14.173228 | F13: =1/(E13*24) -> 0.0029398148
A14: 36929.88 | B14: 6 | C14: 0.017534722 | D14: 192 | E14: =(B14-B13)/((C14-C13)*24) -> 14.876033 | F14: =1/(E14*24) -> 0.0028009259
A16: 36937.474 | B16: 1 | C16: 0.0030671296 | D16: 154 | E16: =(B16-B15)/((C16-C15)*24) -> 13.584906 | F16: =1/(E16*24) -> 0.0030671296
... A255: 37050.713 | B255: 10.26 | C255: 0.032667824 | D255: 152 | E255: =(B255-B254)/((C255-C254)*24) -> 12.446809 | F255: =1/(E255*24) -> 0.0033475783
A257: 13:6/2001 18:42 | B257: 1 | C257: 0.0029467593 | D257: 151 | E257: =(B257-B256)/((C257-C256)*24) -> 14.139827 | F257: =1/(E257*24) -> 0.0029467593
A258: 13:6/2001 18:42 | B258: 2 | C258: 0.0062291667 | D258: 150 | E258: =(B258-B257)/((C258-C257)*24) -> 12.693935 | F258: =1/(E258*24) -> 0.0032824074
A259: 13:6/2001 18:42 | B259: 3 | C259: 0.0095775463 | D259: 150 | E259: =(B259-B258)/((C259-C258)*24) -> 12.44383 | F259: =1/(E259*24) -> 0.0033483796
A260: 13:6/2001 18:42 | B260: 4 | C260: 0.012930556 | D260: 151 | E260: =(B260-B259)/((C260-C259)*24) -> 12.426648 | F260: =1/(E260*24) -> 0.0033530093
A261: 13:6/2001 18:42 | B261: 6.35 | C261: 0.020969907 | D261: 149 | E261: =(B261-B260)/((C261-C260)*24) -> 12.179672 | F261: =1/(E261*24) -> 0.0034210008
A263: 37058.769 | B263: 1 | C263: 0.0025509259 | D263: 163 | E263: =(B263-B256)/((C263-C256)*24) -> 16.333938 | F263: =1/(E263*24) -> 0.0025509259
A264: 37058.769 | B264: 2 | C264: 0.0052337963 | D264: 175 | E264: =(B264-B263)/((C264-C263)*24) -> 15.53063 | F264: =1/(E264*24) -> 0.0026828704
A265: 37058.769 | B265: 3 | C265: 0.0079131944 | D265: 176 | E265: =(B265-B264)/((C265-C264)*24) -> 15.550756 | F265: =1/(E265*24) -> 0.0026793981
A266: 37058.769 | B266: 4 | C266: 0.010611111 | D266: 179 | E266: =(B266-B265)/((C266-C265)*24) -> 15.444015 | F266: =1/(E266*24) -> 0.0026979167
A267: 37058.769 | B267: 5 | C267: 0.013332176 | D267: 180 | E267: =(B267-B266)/((C267-C266)*24) -> 15.312633 | F267: =1/(E267*24) -> 0.0027210648
A268: 37058.769 | B268: 6 | C268: 0.016006944 | D268: 183 | E268: =(B268-B267)/((C268-C267)*24) -> 15.577672 | F268: =1/(E268*24) -> 0.0026747685
A269: 37058.769 | B269: 7 | C269: 0.018686343 | D269: 186 | E269: =(B269-B268)/((C269-C268)*24) -> 15.550756 | F269: =1/(E269*24) -> 0.0026793981
A270: 37058.769 | B270: 8 | C270: 0.021331019 | D270: 188 | E270: =(B270-B269)/((C270-C269)*24) -> 15.754923 | F270: =1/(E270*24) -> 0.0026446759
A271: 37058.769 | B271: 9 | C271: 0.023905093 | D271: 194 | E271: =(B271-B270)/((C271-C270)*24) -> 16.18705 | F271: =1/(E271*24) -> 0.0025740741
A273: 37145.472 | B273: 1 | C273: 0.0031111111 | D273: 159 | E273: =(B273-B272)/((C273-C272)*24) -> 13.392857 | F273: =1/(E273*24) -> 0.0031111111
A274: 37145.472 | B274: 2 | C274: 0.0067210648 | D274: 163 | E274: =(B274-B273)/((C274-C273)*24) -> 11.542161 | F274: =1/(E274*24) -> 0.0036099537
A275: 37145.472 | B275: 3 | C275: 0.010489583 | D275: 164 | E275: =(B275-B274)/((C275-C274)*24) -> 11.056511 | F275: =1/(E275*24) -> 0.0037685185
A276: 37145.472 | B276: 4 | C276: 0.014506944 | D276: 164 | E276: =(B276-B275)/((C276-C275)*24) -> 10.371651 | F276: =1/(E276*24) -> 0.0040173611
... A305: 37171.45 | B305: 10.25 | C305: 0.041979167 | D305: 205 | E305: =(B305-B304)/((C305-C304)*24) -> 18.75 | F305: =1/(E305*24) -> 0.0022222222
A307: 37174.878 | B307: 1 | C307: 0.0034861111 | D307: 152 | E307: =(B307-B294)/((C307-C294)*24) -> 11.952191 | F307: =1/(E307*24) -> 0.0034861111
A308: 37174.878 | B308: 2 | C308: 0.0074143519 | D308: 158 | E308: =(B308-B307)/((C308-C307)*24) -> 10.606953 | F308: =1/(E308*24) -> 0.0039282407
A309: 37174.878 | B309: 3 | C309: 0.011341435 | D309: 158 | E309: =(B309-B308)/((C309-C308)*24) -> 10.61008 | F309: =1/(E309*24) -> 0.0039270833
A310: 37174.878 | B310: 4 | C310: 0.015277778 | D310: 158 | E310: =(B310-B309)/((C310-C309)*24) -> 10.585122 | F310: =1/(E310*24) -> 0.0039363426
A311: 37174.878 | B311: 5 | C311: 0.019295139 | D311: 158 | E311: =(B311-B310)/((C311-C310)*24) -> 10.371651 | F311: =1/(E311*24) -> 0.0040173611
A312: 37174.878 | B312: 6 | C312: 0.021876157 | D312: 183 | E312: =(B312-B311)/((C312-C311)*24) -> 16.143498 | F312: =1/(E312*24) -> 0.0025810185
...

Sheet Hartslagen
A1: DatumTijd | B1: Tijden | C1: HartSlag
A2: 36926.769 | B2: 0 | C2: 115
A3: 36926.769 | B3: 0.00069444444 | C3: 159
A4: 36926.769 | B4: 0.0013888889 | C4: 170
A5: 36926.769 | B5: 0.0020833333 | C5: 177
A6: 36926.769 | B6: 0.0027777778 | C6: 177
A7: 36926.769 | B7: 0.0034722222 | C7: 179
A8: 36926.769 | B8: 0.0041666667 | C8: 178
A9: 36926.769 | B9: 0.0048611111 | C9: 181
A10: 36926.769 | B10: 0.0055555556 | C10: 183
A11: 36926.769 | B11: 0.00625 | C11: 184
A12: 36926.769 | B12: 0.0069444444 | C12: 183
A13: 36926.769 | B13: 0.0076388889 | C13: 184
... A3018: 37408 | B3018: 0.033333333 | C3018: 183
A3019: 37408 | B3019: 0.034027778
A3020: 37414.726 | B3020: 0 | C3020: 97
A3021: 37414.726 | B3021: 0.00017361111 | C3021: 135
A3022: 37414.726 | B3022: 0.00034722222 | C3022: 145
A3023: 37414.726 | B3023: 0.00052083333 | C3023: 149
A3024: 37414.726 | B3024: 0.00069444444 | C3024: 151
A3025: 37414.726 | B3025: 0.00086805556 | C3025: 157
A3026: 37414.726 | B3026: 0.0010416667 | C3026: 158
A3027: 37414.726 | B3027: 0.0012152778 | C3027: 160
A3028: 37414.726 | B3028: 0.0013888889 | C3028: 158
A3029: 37414.726 | B3029: 0.0015625 | C3029: 161
A3030: 37414.726 | B3030: 0.0017361111 | C3030: 161
A3031: 37414.726 | B3031: 0.0019097222 | C3031: 163
... A3828: 37621 | B3828: 0.0045138889 | C3828: 119
A3829: 37621 | B3829: 0.0045717593 | C3829: 120 | D3829: Einde test 1 = 6:39.0 | G3829: =AVERAGE(C3750:C3829) -> 116.4625
A3830: 37621 | B3830: 0.0046296296 | C3830: 119
A3831: 37621 | B3831: 0.0046875 | C3831: 117
A3832: 37621 | B3832: 0.0047453704 | C3832: 116
A3833: 37621 | B3833: 0.0048032407 | C3833: 114
A3834: 37621 | B3834: 0.0048611111 | C3834: 102
A3835: 37621 | B3835: 0.0049189815 | C3835: 92
A3836: 37621 | B3836: 0.0049768519 | C3836: 90
A3837: 37621 | B3837: 0.0050347222 | C3837: 88
A3838: 37621 | B3838: 0.0050925926 | C3838: 88
A3839: 37621 | B3839: 0.005150463 | C3839: 82
A3840: 37621 | B3840: 0.0052083333 | C3840: 79
...

Sheet Calculator
A1: EINDTIJD CALCULATOR
I2: =B20 -> 0.003209306 | J2: 1 | K2: gemid | L2: km/u
A3: T2 = T1 x (D2/D1)^1.06 | E3: max | F3: 186 | I3: =$I$2*J3 -> 0.006418612 | J3: 2 | K3: 140 | L3: =(K3-$B$29)/$B$28 -> 13.129974 | M3: =1/(L3*24) -> 0.0031734006
E4: rust | F4: 48 | I4: =$I$2*J4 -> 0.009627918 | J4: 3 | K4: 141 | L4: =(K4-$B$29)/$B$28 -> 13.24336 | M4: =1/(L4*24) -> 0.0031462309
I5: =$I$2*J5 -> 0.012837224 | J5: 4 | K5: 142 | L5: =(K5-$B$29)/$B$28 -> 13.356746 | M5: =1/(L5*24) -> 0.0031195224
A6: D1 (afstand) | B6: 21.1 | E6: LSD | F6: 66 | G6: =($F$3-$F$4)*F6/100+$F$4 -> 139.08 | I6: =$I$2*J6 -> 0.01604653 | J6: 5 | K6: 143 | L6: =(K6-$B$29)/$B$28 -> 13.470132 | M6: =1/(L6*24) -> 0.0030932635
A7: T1 (tijd) | B7: 0.059016204 | C7: =B7/B6 -> 0.0027969765 | F7: 72 | G7: =($F$3-$F$4)*F7/100+$F$4 -> 147.36 | I7: =$I$2*J7 -> 0.019255836 | J7: 6 | K7: 144 | L7: =(K7-$B$29)/$B$28 -> 13.583518 | M7: =1/(L7*24) -> 0.003067443
C8: =1/(24*C7) -> 14.897039 | I8: =$I$2*J8 -> 0.022465142 | J8: 7 | K8: 145 | L8: =(K8-$B$29)/$B$28 -> 13.696904 | M8: =1/(L8*24) -> 0.00304205
E9: EXT | F9: 73 | G9: =($F$3-$F$4)*F9/100+$F$4 -> 148.74 | I9: =$I$2*J9 -> 0.025674448 | J9: 8 | K9: 146 | L9: =(K9-$B$29)/$B$28 -> 13.81029 | M9: =1/(L9*24) -> 0.003017074
A10: D2 | B10: 42.2 | F10: 76 | G10: =($F$3-$F$4)*F10/100+$F$4 -> 152.88 | I10: =$I$2*J10 -> 0.028883754 | J10: 9 | K10: 147 | L10: =(K10-$B$29)/$B$28 -> 13.923676 | M10: =1/(L10*24) -> 0.0029925048
A11: T2 (berekend) | B11: =B7*POWER(B10/B6,1.06) -> 0.12304474 | C11: =B11/B10 -> 0.0029157522 | I11: =$I$2*J11 -> 0.03209306 | J11: 10 | K11: 148 | L11: =(K11-$B$29)/$B$28 -> 14.037062 | M11: =1/(L11*24) -> 0.0029683325
C12: =1/(24*C11) -> 14.290195 | E12: INT | F12: 77 | G12: =($F$3-$F$4)*F12/100+$F$4 -> 154.26 | I12: =$I$2*J12 -> 0.035302366 | J12: 11 | K12: 149 | L12: =(K12-$B$29)/$B$28 -> 14.150448 | M12: =1/(L12*24) -> 0.0029445476
F13: 84 | G13: =($F$3-$F$4)*F13/100+$F$4 -> 163.92 | I13: =$I$2*J13 -> 0.038511672 | J13: 12 | K13: 150 | L13: =(K13-$B$29)/$B$28 -> 14.263834 | M13: =1/(L13*24) -> 0.0029211408
A14: min / km | B14: 0.0031828704 | I14: =$I$2*J14 -> 0.041720978 | J14: 13 | K14: 151 | L14: =(K14-$B$29)/$B$28 -> 14.37722 | M14: =1/(L14*24) -> 0.0028981032
A15: afstand | B15: 42.195 | E15: Recu | F15: 65 | G15: =($F$3-$F$4)*F15/100+$F$4 -> 137.7 | I15: =$I$2*J15 -> 0.044930284 | J15: 14 | K15: 152 | L15: =(K15-$B$29)/$B$28 -> 14.490606 | M15: =1/(L15*24) -> 0.0028754261
A16: eindtijd | B16: =B14*B15 -> 0.13430122 | I16: =$I$2*J16 -> 0.04813959 | J16: 15 | K16: 153 | L16: =(K16-$B$29)/$B$28 -> 14.603992 | M16: =1/(L16*24) -> 0.0028531012
E17: Tempo | F17: 85 | G17: =($F$3-$F$4)*F17/100+$F$4 -> 165.3 | I17: =$I$2*J17 -> 0.051348896 | J17: 16 | K17: 154 | L17: =(K17-$B$29)/$B$28 -> 14.717378 | M17: =1/(L17*24) -> 0.0028311202
A18: eindtijd | B18: 0.13541667 | F18: 90 | G18: =($F$3-$F$4)*F18/100+$F$4 -> 172.2 | I18: =$I$2*J18 -> 0.054558202 | J18: 17 | K18: 155 | L18: =(K18-$B$29)/$B$28 -> 14.830764 | M18: =1/(L18*24) -> 0.0028094754
A19: afstand | B19: 42.195 | I19: =$I$2*J19 -> 0.057767508 | J19: 18 | K19: 156 | L19: =(K19-$B$29)/$B$28 -> 14.94415 | M19: =1/(L19*24) -> 0.002788159
A20: min / km | B20: =B18/B19 -> 0.003209306 | I20: =$I$2*J20 -> 0.060976814 | J20: 19 | K20: 157 | L20: =(K20-$B$29)/$B$28 -> 15.057536 | M20: =1/(L20*24) -> 0.0027671637
A21: km / u | B21: =1/(24*B20) -> 12.983077 | I21: =$I$2*J21 -> 0.06418612 | J21: 20 | K21: 158 | L21: =(K21-$B$29)/$B$28 -> 15.170922 | M21: =1/(L21*24) -> 0.0027464821
I22: =$I$2*J22 -> 0.067395426 | J22: 21 | K22: 159 | L22: =(K22-$B$29)/$B$28 -> 15.284308 | M22: =1/(L22*24) -> 0.0027261075
A23: km / u | B23: 14.78 | I23: =$I$2*J23 -> 0.067716357 | J23: 21.1 | K23: 160 | L23: =(K23-$B$29)/$B$28 -> 15.397694 | M23: =1/(L23*24) -> 0.0027060329
A24: min / km | B24: =1/(B23*24) -> 0.0028191249 | K24: 161 | L24: =(K24-$B$29)/$B$28 -> 15.51108 | M24: =1/(L24*24) -> 0.0026862518
K25: 162 | L25: =(K25-$B$29)/$B$28 -> 15.624466 | M25: =1/(L25*24) -> 0.0026667578
A26: min / km | B26: 0.0027777778 | K26: 163 | L26: =(K26-$B$29)/$B$28 -> 15.737852 | M26: =1/(L26*24) -> 0.0026475447
A27: km / u | B27: =1/(24*B26) -> 15 | K27: 164 | L27: =(K27-$B$29)/$B$28 -> 15.851238 | M27: =1/(L27*24) -> 0.0026286064
A28: Ri.Co | B28: =SLOPE(Reeksen!$E$706:$E$710,Reeksen!$I$706:$I$710) -> 8.8194289 | K28: 165 | L28: =(K28-$B$29)/$B$28 -> 15.964624 | M28: =1/(L28*24) -> 0.0026099372
A29: Nul punt | B29: =INTERCEPT(Reeksen!$E$706:$E$710,Reeksen!$I$706:$I$710) -> 24.201131 | K29: 166 | L29: =(K29-$B$29)/$B$28 -> 16.07801 | M29: =1/(L29*24) -> 0.0025915313
A30: HS | B30: =$B$28*B27+$B$29 -> 156.49256 | K30: 167 | L30: =(K30-$B$29)/$B$28 -> 16.191396 | M30: =1/(L30*24) -> 0.0025733832
A31: Instel HS | B31: =ROUND(B30,0)+2 -> 158 | K31: 168 | L31: =(K31-$B$29)/$B$28 -> 16.304782 | M31: =1/(L31*24) -> 0.0025554875
K32: 169 | L32: =(K32-$B$29)/$B$28 -> 16.418168 | M32: =1/(L32*24) -> 0.0025378389
A33: 1kg body fat equals 7.727kCal. | K33: 170 | L33: =(K33-$B$29)/$B$28 -> 16.531554 | M33: =1/(L33*24) -> 0.0025204325
K34: 171 | L34: =(K34-$B$29)/$B$28 -> 16.64494 | M34: =1/(L34*24) -> 0.0025032632
A35: Hartslagzones ASICS | K35: 172 | L35: =(K35-$B$29)/$B$28 -> 16.758326 | M35: =1/(L35*24) -> 0.0024863262
K36: 173 | L36: =(K36-$B$29)/$B$28 -> 16.871712 | M36: =1/(L36*24) -> 0.0024696169
A37: Rust: minder dan 135 slagen per minuut | K37: 174 | L37: =(K37-$B$29)/$B$28 -> 16.985099 | M37: =1/(L37*24) -> 0.0024531307
A38: Warming-up: tussen de 121 en de 149 slagen per minuut | K38: 175 | L38: =(K38-$B$29)/$B$28 -> 17.098485 | M38: =1/(L38*24) -> 0.0024368631
A39: Rustig hardlopen: tussen de 135 en de 149 slagen per minuut | K39: 176 | L39: =(K39-$B$29)/$B$28 -> 17.211871 | M39: =1/(L39*24) -> 0.0024208099
A40: Hardlopen: tussen de 149 en de 169 slagen per minuut | K40: 177 | L40: =(K40-$B$29)/$B$28 -> 17.325257 | M40: =1/(L40*24) -> 0.0024049668
...

Sheet Parcours
A1: km 1 | B1: Eerste wegversmalling Sluisstraat
A2: km 2 | B2: Diepestraat, midden platen kot Fik Smeyers
A3: km 3 | B3: Mirramar, begin oprit na hoek/bocht Sibelco
A4: km 4 | B4: Mirramar, Verlichtingspaal na huisnummer 37
A5: km 5 | B5: Turnhoutsebaan, brug/uitrit van huisnummer 54, eerste wit huis na Runners Service
A6: km 6 | B6: Turnhoutsebaan, begin stoep/klinkers auto's Eddy
A7: Totaal 6,35 km
A9: km 1 | B9: Schuin voor Tegelidee
A10: km 2 | B10: Voor nieuwe villa Miramar
A11: km 3 | B11: Mirramar Nr.83 (nieuwe boompjes)
A12: km 4 | B12: Achter dubbelle bocht (3de wei-paal)
A13: km 5 | B13: Telefoonkot
A14: km 6 | B14: Einde parking Luc Put
A15: km 7 | B15: Eerste boompje Kapellestraat
A16: km 8 | B16: Galbergen nr 15 (eerste wit huis aan linkerkant)
A17: km 9 | B17: Kruispunt in bos aan SV Mol
A18: km 10 | B18: Sluis aan bord 70 km/uur
A19: Totaal 10,25
A21: km 5 | B21: 1ste verlichtingspaal op de brug van Mol-Donk
A22: km 10 | B22: paadje naar weide achter lang smal bos achter 1ste boerderij
A23: km 15 | B23: Coax box Frankfurtlaan nr 7 Nieuwe beige villa Europese Wijk
A24: km 20 | B24: Poort Visvervoer Postelarenweg. 20m voor 1ste kruispunt
A25: Totaal 24,66 km
A27: Hoekse Sport
A29: Lopen in de corner driehoeken en voor de goalen
A32: 1 ronde | B32: =156*4+177*2 -> 978 | C32: voeten
A33: 1 voet | B33: 30 | C33: cm
A34: 978 voeten | B34: =B32*B33/100 -> 293.4 | C34: m
A35: 1 ronde | B35: =B34/1000 -> 0.2934 | C35: km
A37: Van 1 tot 2 | B37: 156 | C37: voeten
A38: Van 2 tot 3 | B38: 156 | C38: voeten
A39: Van 3 to 4 | B39: 177 | C39: voeten
A40: Van 4 to 5 | B40: 156 | C40: voeten
A41: Van 5 tot 6 | B41: 156 | C41: voeten
A42: Van 6 tot 1 | B42: 177 | C42: voeten

Sheet HM in 1'10"
E1: Trainingschema halve marathon in 1hr10' | I1: 10 km in 32'
E2: .
E3: VW 10 km in 32'00/120 tot 150 km per week in 7 trainingen
A6: 38481 | B6: 1 | C6: ma | D6: 20 | E6: 20 km in 1hr20'(4'00" /km) | H6: 24 | I6: Ma : 24 km in 1h48' (4'30" /km)
A7: =A6+1 -> 38482 | B7: 1 | C7: di | D7: 12 | E7: 12 km in 41' , (3'25" / km) | H7: 8 | I7: Di : 8 x 1 km in 3'10", dribbelpauze 2'
A8: =A7+1 -> 38483 | B8: 1 | C8: wo | D8: 15 | E8: 15 km in 1h08'(4'30" / km) | H8: 20 | I8: Wo : 20 km in 1h20' (4'00" / km)
A9: =A8+1 -> 38484 | B9: 1 | C9: do | D9: 8 | E9: 8 x 1 km in 3'15", dribbelpauze 2' | H9: 21 | I9: Do : 1hr30' lopen
A10: =A9+1 -> 38485 | B10: 1 | C10: vr | D10: 20 | E10: 20 km in 1h20'(4'00" / km) | I10: VR : R
A11: =A10+1 -> 38486 | B11: 1 | C11: za | D11: 25 | E11: 25 km in 2hr18' (5'30" / km) | H11: 25 | I11: Za : 25 km in 1h44' (4'10" / km)
A12: =A11+1 -> 38487 | B12: 1 | C12: zo | D12: 10 | E12: 10 km in 37'30"(3'45" / km) | F12: =SUM(D6:D12) -> 110 | H12: 12 | I12: Zo : 12 km in 41'00" (3'25" / km) | J12: =SUM(H6:H12) -> 110
A13: =A12+1 -> 38488 | B13: 2 | C13: ma | D13: 20 | E13: 20 km in 1hr20'(4'00" /km) | H13: 24 | I13: Ma : 24 km in 1h48' (4'30" /km)
A14: =A13+1 -> 38489 | B14: 2 | C14: di | D14: 12 | E14: 12 km in 41' , (3'25" / km) | H14: 8 | I14: Di : 8 x 1 km in 3'10", dribbelpauze 2'
A15: =A14+1 -> 38490 | B15: 2 | C15: wo | D15: 15 | E15: 15 km in 1h08'(4'30" / km) | H15: 10 | I15: Wo : 20 km in 1h20' (4'00" / km)
A16: =A15+1 -> 38491 | B16: 2 | C16: do | D16: 8 | E16: 8 x 1 km in 3'15", dribbelpauze 2' | H16: 21 | I16: Do : 1hr30' lopen
A17: =A16+1 -> 38492 | B17: 2 | C17: vr | D17: 20 | E17: 20 km in 1h20'(4'00" / km) | I17: VR : R
A18: =A17+1 -> 38493 | B18: 2 | C18: za | D18: 25 | E18: 25 km in 2hr18' (5'30" / km) | H18: 25 | I18: Za : 25 km in 1h44' (4'10" / km)
A19: =A18+1 -> 38494 | B19: 2 | C19: zo | D19: 10 | E19: 10 km in 37'30"(3'45" / km) | F19: =SUM(D13:D19) -> 110 | H19: 12 | I19: Zo : 12 km in 41'00" (3'25" / km) | J19: =SUM(H13:H19) -> 100
A20: =A19+1 -> 38495 | B20: 3 | C20: ma | D20: 25 | E20: 25 km in 1h44' (4'10" / km)
A21: =A20+1 -> 38496 | B21: 3 | C21: di | D21: 8 | E21: 8 x 1 km in 3'15", dribbelpauze 2' | H21: 20 | I21: Di : 20 km uur 1hr30' (4'30" / km)
A22: =A21+1 -> 38497 | B22: 3 | C22: wo | D22: 15 | E22: 15 km in 1h08'(4'30" / km) | H22: 22 | I22: Wo : 22 km in 2hr01' (5'30" / km)
A23: =A22+1 -> 38498 | B23: 3 | C23: do | D23: 6 | E23: 20 x 300 m in 1'01", dribbelpauze 30" | H23: 20 | I23: Do : 20 km in 1hr20' (4'00" / km)
A24: =A23+1 -> 38499 | B24: 3 | C24: vr | D24: 10 | E24: 10 km in 37'30"(3'45" / km) | H24: 10 | I24: Vr : 10 km in 37'30"(3'45" / km)
A25: =A24+1 -> 38500 | B25: 3 | C25: za | D25: 10 | E25: 10 km in 45' (4'30" / km) | H25: 15 | I25: Za : 15 km in 1hr08'(4'30" / km)
A26: =A25+1 -> 38501 | B26: 3 | C26: zo | D26: 10 | E26: 10 km in 32'30"(3'15" / km) | F26: =SUM(D20:D26) -> 84 | H26: 5 | I26: Zo : TEST 5 km in 16'00" (3'12" / km) | J26: =SUM(H20:H26) -> 92
A27: =A26+1 -> 38502 | B27: 4 | C27: ma | D27: 15 | E27: 15 km in 1h08' (4'30" / km) | H27: 15 | I27: Ma : 15 km in 1hr08' (4'30" / km)
A28: =A27+1 -> 38503 | B28: 4 | C28: di | D28: 15 | E28: 15 x 1 km in 3'30", dribbelpauze 1' | H28: 20 | I28: Di : 20 km in 1hr20' (4'00" / km)
A29: =A28+1 -> 38504 | B29: 4 | C29: wo | D29: 25 | E29: 25 km in 1h44'(4'10" / km) | H29: 9 | I29: Wo : 3 x 3 km in 10'15", dribbelpauze 4'
A30: =A29+1 -> 38505 | B30: 4 | C30: do | D30: 15 | E30: 15 km in 58'45"(3'55" / km) | H30: 15 | I30: Do : 15 km in 1hr08' (4'30" / km)
A31: =A30+1 -> 38506 | B31: 4 | C31: vr | D31: 9 | E31: 3 x 3 km in 10'15", dribbelpauze 5' | H31: 15 | I31: Vr : 15 km in 58'45" (3'55" / km)
A32: =A31+1 -> 38507 | B32: 4 | C32: za | D32: 25 | E32: 25 km in 1h44'(4'10" / km) | H32: 22 | I32: Za : 22 km in 2h01'(5'30" / km)
A33: =A32+1 -> 38508 | B33: 4 | C33: zo | D33: 20 | E33: 20 km in 1h20' (4'00" / km) | F33: =SUM(D27:D33) -> 124 | H33: 20 | I33: Zo : 20 km in 1h20' (4'00" / km) | J33: =SUM(H27:H33) -> 116
A34: =A33+1 -> 38509 | B34: 5 | C34: ma | D34: 15 | E34: 15 km in 58'45"(3'55" / km) | H34: 15 | I34: Ma : 15 km in 1hr08'(4'30" /km)
A35: =A34+1 -> 38510 | B35: 5 | C35: di | D35: 20 | E35: 20 km in 1h28' (4'00" / km) | H35: 10 | I35: Di : 10 x 1 km in 3'10" , dribbelpauze 2'
A36: =A35+1 -> 38511 | B36: 5 | C36: wo | D36: 8 | E36: 8 x 1 km in 3'12", dribbelpauze 2' | H36: 20 | I36: Wo : 20 km in 1hr20' (4'00" / km)
A37: =A36+1 -> 38512 | B37: 5 | C37: do | D37: 20 | E37: 20 km in 1h20'(4'00" / km) | H37: 21 | I37: Do : 1hr30' lopen
A38: =A37+1 -> 38513 | B38: 5 | C38: vr | D38: 15 | E38: 15 km in 1h08'(4'30" / km) | H38: 20 | I38: Vr : 20 km in 1hr30' (4'30" / km)
A39: =A38+1 -> 38514 | B39: 5 | C39: za | D39: 13 | E39: 13 km in 44'25" (3'25" / km) | H39: 25 | I39: Za : 25 km in 1hr44' (4'10" / km)
A40: =A39+1 -> 38515 | B40: 5 | C40: zo | D40: 25 | E40: 25 km in 2h18' (5'30" / km) | F40: =SUM(D34:D40) -> 116 | H40: 12 | I40: Zo : 12 km in 41' (3'25" / km) | J40: =SUM(H34:H40) -> 123
A41: =A40+1 -> 38516 | B41: 6 | C41: ma | D41: 15 | E41: 15 km in 58'45"(3'55" / km) | H41: 15 | I41: Ma : 15 km in 1hr08'(4'30" /km)
A42: =A41+1 -> 38517 | B42: 6 | C42: di | D42: 20 | E42: 20 km in 1h28' (4'00" / km) | H42: 10 | I42: Di : 10 x 1 km in 3'10" , dribbelpauze 2'
...

Sheet Conconi 2
A1: Time | B1: HF | C1: km/u
A2: 0 | B2: 69
A3: 5.787037e-05 | B3: 69
A4: 0.00011574074 | B4: 86
A5: 0.00017361111 | B5: 93
A6: 0.00023148148 | B6: 96
A7: 0.00028935185 | B7: 97
A8: 0.00034722222 | B8: 97
A9: 0.00040509259 | B9: 93
A10: 0.00046296296 | B10: 88
A11: 0.00052083333 | B11: 92
A12: 0.0005787037 | B12: 92
A13: 0.00063657407 | B13: 90
A14: 0.0006712963 | C14: 4.5
A15: 0.00069444444 | B15: 87 | C15: 4.5
A16: 0.00075231481 | B16: 94 | C16: 4.5
A17: 0.00081018519 | B17: 97 | C17: 4.5
A18: 0.00086805556 | B18: 99 | C18: 4.5
A19: 0.00092592593 | B19: 100 | C19: 4.5
A20: 0.0009837963 | B20: 101 | C20: 4.5
A21: 0.0010416667 | B21: 101 | C21: 4.5
A22: 0.001099537 | B22: 99 | C22: 4.5
A23: 0.0011574074 | B23: 100 | C23: 4.5
A24: 0.0012152778 | B24: 99 | C24: 4.5
A25: 0.0012731481 | B25: 99 | C25: 4.5
A26: 0.0013310185 | B26: 97 | C26: 4.5
... A87: 0.0048611111 | B87: 103 | C87: 5.5
A88: 0.0048726852 | C88: 6.5
A89: 0.0049189815 | B89: 105 | C89: 6.5
A90: 0.0049768519 | B90: 107 | C90: 6.5
A91: 0.0050347222 | B91: 107 | C91: 6.5
A92: 0.0050925926 | B92: 108 | C92: 6.5
A93: 0.005150463 | B93: 109 | C93: 6.5
A94: 0.0052083333 | B94: 110 | C94: 6.5
A95: 0.0052662037 | B95: 110 | C95: 6.5
A96: 0.0053240741 | B96: 110 | C96: 6.5
A97: 0.0053819444 | B97: 109 | C97: 6.5
A98: 0.0054398148 | B98: 109 | C98: 6.5
A99: 0.0054976852 | B99: 110 | C99: 6.5
A100: 0.0055555556 | B100: 110 | C100: 6.5
...

Sheet Conconi 3
A1: Time | B1: HF | C1: Km/u
A2: 0 | B2: 88 | C2: 7 | F2: 7 | G2: 114
A3: 5.787037e-05 | B3: 88 | C3: 7 | F3: 7.5 | G3: 124
A4: 0.00011574074 | B4: 96 | C4: 7 | F4: 8 | G4: 133
A5: 0.00017361111 | B5: 108 | C5: 7 | F5: 8.5 | G5: 135
A6: 0.00023148148 | B6: 115 | C6: 7 | F6: 9 | G6: 141
A7: 0.00028935185 | B7: 117 | C7: 7 | F7: 9.5 | G7: 143
A8: 0.00034722222 | B8: 118 | C8: 7 | F8: 10 | G8: 148
A9: 0.00040509259 | B9: 119 | C9: 7 | F9: 10.5 | G9: 150
A10: 0.00046296296 | B10: 117 | C10: 7
A11: 0.00052083333 | B11: 116 | C11: 7
A12: 0.0005787037 | B12: 116 | C12: 7
A13: 0.00063657407 | B13: 114 | C13: 7
A14: 0.00069444444 | B14: 115 | C14: 7
A15: 0.00075231481 | B15: 117 | C15: 7
A16: 0.00081018519 | B16: 116 | C16: 7
A17: 0.00086805556 | B17: 116 | C17: 7
A18: 0.00092592593 | B18: 116 | C18: 7
A19: 0.0009837963 | B19: 116 | C19: 7
A20: 0.0010416667 | B20: 117 | C20: 7
A21: 0.001099537 | B21: 117 | C21: 7
... A136: 0.0077546296 | B136: 151 | C136: 10.5

Sheet Tijd 2000
A1: Datum | B1: T1 | C1: T2 | D1: T3 | E1: T4 | F1: T5 | G1: T6 | H1: T7 | I1: T8 | J1: T9 | K1: T10 | L1: T11 | M1: T12 | N1: T13 | O1: T14 | P1: Totaal | Q1: afstand | R1: Totaal/km | S1: MAX | T1: Gemid | U1: H1 | V1: H2 | W1: H3 | X1: H4 | Y1: H5 | Z1: H6 | AA1: H7 | AB1: H8 | AC1: H9 | AD1: H10 | AE1: H11 | AF1: H12 | AG1: H13
A2: 36605 | B2: 0.0033122685 | C2: 0.0032060185 | D2: 0.003124537 | E2: 0.0032033565 | F2: 0.0033252315 | G2: 0.0032372685 | H2: 0.0010736111 | P2: =SUM(B2:H2) -> 0.020482292 | Q2: 6.35 | R2: =$P$2/$Q$2 -> 0.0032255577
A3: 36608 | B3: 0.003387037 | C3: 0.0031563657 | D3: 0.0031986111 | E3: 0.0031388889 | F3: 0.003172338 | G3: 0.0031508102 | H3: 0.0010604167 | P3: =SUM(B3:H3) -> 0.020264468 | Q3: 6.35 | R3: =$P$3/$Q$3 -> 0.0031912547
A4: 36610 | B4: 0.0031712963 | C4: 0.0031232639 | D4: 0.0031 | E4: 0.003147338 | F4: 0.0036655093 | G4: 0.0031174769 | H4: 0.0010827546 | P4: =SUM(B4:H4) -> 0.020407639 | Q4: 6.35 | R4: =$P$4/$Q$4 -> 0.0032138014
A5: 36612 | B5: 0.0031712963 | C5: 0.0032752315 | D5: 0.0031993056 | E5: 0.0030900463 | F5: 0.0030868056 | G5: 0.0029928241 | H5: 0.00095590278 | P5: =SUM(B5:H5) -> 0.019771412 | Q5: 6.35 | R5: =$P$5/$Q$5 -> 0.0031136082
A6: 36614 | B6: 0.0031053241 | C6: 0.00309375 | D6: 0.0031064815 | E6: 0.00309375 | F6: 0.0030497685 | G6: 0.0031134259 | H6: 0.00090393519 | P6: =SUM(B6:H6) -> 0.019466435 | Q6: 6.35 | R6: =$P$6/$Q$6 -> 0.0030655803 | S6: 200 | T6: 183 | U6: 159 | V6: 181 | W6: 188 | X6: 188 | Y6: 188 | Z6: 192
A7: 36615 | B7: 0.00321875 | C7: 0.0031666667 | D7: 0.0032824074 | E7: 0.0033587963 | F7: 0.0031215278 | G7: 0.0033055556 | H7: 0.0010127315 | P7: =SUM(B7:H7) -> 0.020466435 | Q7: 6.35 | R7: =$P$7/$Q$7 -> 0.0032230607 | S7: 187 | T7: 171 | U7: 154 | V7: 172 | W7: 173 | X7: 174 | Y7: 175 | Z7: 178
A8: 36616 | B8: 0.0029594907 | C8: 0.003025463 | D8: 0.0029826389 | E8: 0.0029976852 | F8: 0.0030081019 | G8: 0.0029398148 | H8: 0.00090046296 | P8: =SUM(B8:H8) -> 0.018813657 | Q8: 6.35 | R8: =$P$8/$Q$8 -> 0.0029627807 | S8: 195 | T8: 180 | U8: 161 | V8: 177 | W8: 181 | X8: 183 | Y8: 185 | Z8: 188
A9: 36618 | P9: 0.039236111 | Q9: 12.7 | R9: =$P$9/$Q$9 -> 0.0030894576
A10: 36619 | B10: 0.0031655093 | C10: 0.0030185185 | D10: 0.0029930556 | E10: 0.0031041667 | F10: 0.003162037 | G10: 0.0032407407 | H10: 0.0010775463 | I10: 0.0032326389 | J10: 0.0027581019 | P10: =SUM(B10:N10) -> 0.025752315 | Q10: 8.35 | R10: =$P$10/$Q$10 -> 0.0030841096 | S10: 190 | T10: 171 | U10: 150 | V10: 166 | W10: 173 | X10: 174 | Y10: 174 | Z10: 173 | AA10: 173 | AB10: 176
A11: 36620 | B11: 0.0030289352 | C11: 0.0028252315 | D11: 0.0028761574 | E11: 0.0028969907 | F11: 0.0029756944 | G11: 0.0029560185 | H11: 0.00091898148 | P11: =SUM(B11:N11) -> 0.018478009 | Q11: 6.35 | R11: =$P$11/$Q$11 -> 0.0029099227 | S11: 188 | T11: 177 | U11: 149 | V11: 166 | W11: 159 | X11: 177 | Y11: 179 | Z11: 182
A12: 36621 | B12: 0.0032106481 | C12: 0.0031030093 | D12: 0.0031157407 | E12: 0.0030358796 | F12: 0.0029976852 | G12: 0.0029861111 | H12: 0.0010497685 | I12: 0.0030729167 | J12: 0.0030902778 | K12: 0.0030856481 | L12: 0.0031018519 | M12: 0.0031296296 | N12: 0.0030289352 | O12: 0.0010231481 | P12: =SUM(B12:O12) -> 0.03903125 | Q12: 12.7 | R12: =$P$12/$Q$12 -> 0.0030733268 | S12: 184 | T12: 176 | U12: 147 | V12: 167 | W12: 173 | X12: 176 | Y12: 177 | Z12: 179 | AA12: 181 | AB12: 180 | AC12: 180 | AD12: 181 | AE12: 181 | AF12: 180 | AG12: 182
A13: 36626 | B13: 0.0031851852 | C13: 0.0030474537 | D13: 0.0032488426 | E13: 0.0033946759 | F13: 0.0034027778 | G13: 0.0031967593 | H13: 0.0010393519 | P13: =SUM(B13:O13) -> 0.020515046 | Q13: 6.35 | R13: =$P$13/$Q$13 -> 0.003230716 | S13: 185 | T13: 170 | U13: 151 | V13: 167 | W13: 173 | X13: 173 | Y13: 174 | Z13: 178 | AA13: 183
A14: 36641 | B14: 0.0029861111 | C14: 0.0028599537 | D14: 0.0031689815 | E14: 0.0033171296 | F14: 0.0030740741 | G14: 0.0029537037 | H14: 0.00087615741 | P14: =SUM(B14:O14) -> 0.019236111 | Q14: 6.35 | R14: =$P$14/$Q$14 -> 0.0030293088 | S14: 201 | T14: 178 | U14: 173 | V14: 179 | W14: 180 | X14: 186 | Y14: 191 | Z14: 191
A15: 36644 | B15: 0.0030428241 | C15: 0.0029791667 | D15: 0.0032013889 | E15: 0.0032361111 | F15: 0.0033935185 | G15: 0.0033865741 | H15: 0.0011527778 | I15: 0.0032962963 | J15: 0.0031655093 | K15: 0.0030740741 | L15: 0.0030196759 | P15: =SUM(B15:O15) -> 0.032947917 | Q15: 10.35 | R15: =$P$15/$Q$15 -> 0.0031833736 | S15: 195 | T15: 179 | U15: 158 | V15: 175 | W15: 178 | X15: 178 | Y15: 179 | Z15: 178 | AA15: 180 | AB15: 182 | AC15: 185 | AD15: 187
A16: 36647 | B16: 0.0030601852 | C16: 0.0029178241 | D16: 0.0030949074 | E16: 0.0030416667 | F16: 0.0030844907 | G16: 0.0029270833 | H16: 0.0009375 | P16: =SUM(B16:O16) -> 0.019063657 | Q16: 6.35 | R16: =$P$16/$Q$16 -> 0.0030021508 | S16: 190 | T16: 174 | U16: 156 | V16: 172 | W16: 175 | X16: 178 | Y16: 178 | Z16: 182
A17: 36654 | B17: 0.0032025463 | C17: 0.0030902778 | D17: 0.0030219907 | E17: 0.0031481481 | F17: 0.003125 | G17: 0.0031840278 | H17: 0.0032997685 | I17: 0.0032268519 | J17: 0.0031354167 | K17: 0.0027627315 | L17: 0.0006875 | P17: =SUM(B17:O17) -> 0.031884259 | Q17: 10.26 | R17: =$P$17/$Q$17 -> 0.0031076276 | S17: 190 | T17: 174 | U17: 153 | V17: 168 | W17: 173 | X17: 174 | Y17: 175 | Z17: 176 | AA17: 176 | AB17: 177 | AC17: 180 | AD17: 184
A18: 36656 | B18: 0.0031342593 | C18: 0.0029571759 | D18: 0.0029803241 | E18: 0.0029826389 | F18: 0.0030092593 | G18: 0.0030335648 | H18: 0.0030393519 | I18: 0.0031145833 | J18: 0.003125 | K18: 0.0027858796 | L18: 0.00067592593 | P18: =SUM(B18:O18) -> 0.030837963 | Q18: 10.26 | R18: =$P$18/$Q$18 -> 0.0030056494 | S18: 190 | T18: 176 | U18: 156 | V18: 167 | W18: 176 | X18: 178 | Y18: 179 | Z18: 179 | AA18: 179 | AB18: 179 | AC18: 179 | AD18: 183
A19: 36658 | B19: 0.0029375 | C19: 0.0029050926 | D19: 0.0028912037 | E19: 0.003 | G19: 0.0062708333 | H19: 0.0030856481 | I19: 0.0030266204 | J19: 0.003125 | K19: 0.0027997685 | L19: 0.00062384259 | P19: =SUM(B19:O19) -> 0.030665509 | Q19: 10.26 | R19: =$P$19/$Q$19 -> 0.0029888411 | S19: 190 | T19: 179 | U19: 162 | V19: 172 | W19: 176 | X19: 178 | Z19: 179 | AA19: 181 | AB19: 183 | AC19: 185 | AD19: 189
A20: 36661 | B20: 0.0031851852 | C20: 0.0030983796 | E20: 0.0058668981 | F20: 0.0030578704 | G20: 0.0030752315 | H20: 0.0030763889 | I20: 0.0031493056 | J20: 0.0031226852 | K20: 0.0028449074 | L20: 0.00069560185 | P20: =SUM(B20:O20) -> 0.031172454 | Q20: 10.26 | R20: =$P$20/$Q$20 -> 0.0030382508 | S20: 185 | T20: 170 | U20: 151 | V20: 161 | X20: 169 | Y20: 172 | Z20: 172 | AA20: 174 | AB20: 173 | AC20: 174 | AD20: 178
A21: 36662 | B21: 0.0029224537 | C21: 0.0027974537 | D21: 0.0028344907 | E21: 0.0027696759 | F21: 0.0027418981 | G21: 0.0026168981 | H21: 0.00083564815 | P21: =SUM(B21:O21) -> 0.017518519 | Q21: 6.35 | R21: =$P$21/$Q$21 -> 0.0027588218 | S21: 192 | T21: 174 | U21: 155 | V21: 171 | W21: 173 | X21: 177 | Y21: 180 | Z21: 185
A22: 36665 | B22: 0.0029837963 | C22: 0.0029409722 | D22: 0.0028946759 | E22: 0.0029861111 | F22: 0.0030821759 | G22: 0.0031319444 | H22: 0.0032361111 | I22: 0.0031736111 | J22: 0.0031342593 | K22: 0.0028206019 | L22: 0.00068402778 | P22: =SUM(B22:O22) -> 0.031068287 | Q22: 10.26 | R22: =$P$22/$Q$22 -> 0.0030280982 | S22: 188 | T22: 173 | U22: 154 | V22: 168 | W22: 173 | X22: 174 | Y22: 175 | Z22: 175 | AA22: 174 | AB22: 174 | AC22: 175 | AD22: 181
A23: 36668 | B23: 0.0029861111 | C23: 0.0029247685 | D23: 0.0029108796 | E23: 0.0029490741 | F23: 0.0030208333 | G23: 0.0030150463 | H23: 0.0031296296 | I23: 0.0030381944 | J23: 0.0030810185 | K23: 0.0028194444 | L23: 0.00070717593 | P23: =SUM(B23:O23) -> 0.030582176 | Q23: 10.26 | R23: =$P$23/$Q$23 -> 0.0029807189 | S23: 184 | T23: 172 | U23: 152 | V23: 166 | W23: 171 | X23: 173 | Y23: 173 | Z23: 175 | AA23: 174 | AB23: 176 | AC23: 177 | AD23: 180
A24: 36669 | B24: 0.0029444444 | C24: 0.0028796296 | D24: 0.0028599537 | E24: 0.0028206019 | F24: 0.0029282407 | G24: 0.0028611111 | H24: 0.0029293981 | I24: 0.0028923611 | J24: 0.0029224537 | K24: 0.0026793981 | L24: 0.00064236111 | P24: =SUM(B24:O24) -> 0.029359954 | Q24: 10.26 | R24: =$P$24/$Q$24 -> 0.0028615939 | S24: 190 | T24: 174 | U24: 154 | V24: 166 | W24: 171 | X24: 174 | Y24: 175 | Z24: 177 | AA24: 179 | AB24: 180 | AC24: 181 | AD24: 185
A25: 36671 | B25: 0.0030115741 | C25: 0.0029710648 | D25: 0.0029155093 | E25: 0.0029722222 | F25: 0.0029965278 | G25: 0.0029872685 | H25: 0.0030081019 | I25: 0.0030023148 | J25: 0.0029918981 | K25: 0.0026875 | L25: 0.00061342593 | P25: =SUM(B25:O25) -> 0.030157407 | Q25: 10.26 | R25: =P25/Q25 -> 0.0029393185 | S25: 192 | T25: 170 | U25: 146 | V25: 164 | W25: 169 | X25: 170 | Y25: 171 | Z25: 173 | AA25: 174 | AB25: 176 | AC25: 176 | AD25: 181
A26: 36675 | B26: 0.0027002315 | C26: 0.0031863426 | D26: 0.0024733796 | E26: 0.0037037037 | F26: 0.0028043981 | G26: 0.0034085648 | H26: 0.0026631944 | I26: 0.0032986111 | J26: 0.0033819444 | K26: 0.0026550926 | L26: 0.00064699074 | P26: =SUM(B26:O26) -> 0.030922454 | Q26: 10.26 | R26: =P26/Q26 -> 0.0030138844 | S26: 182 | T26: 165 | U26: 154 | V26: 161 | W26: 174 | X26: 159 | Y26: 169 | Z26: 165 | AA26: 173 | AB26: 168 | AC26: 161 | AD26: 171
A27: 36677 | B27: 0.0029560185 | C27: 0.0028923611 | D27: 0.0028657407 | E27: 0.0028622685 | F27: 0.0028784722 | G27: 0.0029421296 | H27: 0.00290625 | I27: 0.0029259259 | J27: 0.0029641204 | K27: 0.002556713 | L27: 0.00055092593 | P27: =SUM(B27:O27) -> 0.029300926 | Q27: 10.26 | R27: =P27/Q27 -> 0.0028558407 | S27: 196 | T27: 172 | U27: 155 | V27: 165 | W27: 169 | X27: 173 | Y27: 174 | Z27: 174 | AA27: 174 | AB27: 175 | AC27: 176 | AD27: 183
A28: 36681 | B28: 0.00296875 | C28: 0.0029849537 | D28: 0.0029201389 | E28: 0.0029479167 | F28: 0.0029953704 | G28: 0.003 | H28: 0.0030590278 | I28: 0.0030497685 | J28: 0.0030671296 | K28: 0.0026481481 | L28: 0.00069212963 | P28: =SUM(B28:O28) -> 0.030333333 | Q28: 10.26 | R28: =P28/Q28 -> 0.0029564652 | S28: 187 | T28: 171 | U28: 152 | V28: 163 | W28: 168 | X28: 171 | Y28: 172 | Z28: 175 | AA28: 176 | AB28: 176 | AC28: 176 | AD28: 182
A29: 36731 | B29: 0.0030532407 | C29: 0.0030486111 | D29: 0.0032685185 | E29: 0.0037534722 | F29: 0.0034907407 | G29: 0.0030925926 | H29: 0.0009212963 | P29: =SUM(B29:O29) -> 0.020628472 | Q29: 6.35 | R29: =P29/Q29 -> 0.0032485783 | S29: 200 | T29: 177 | U29: 156 | V29: 173 | W29: 179 | X29: 177 | Y29: 182 | Z29: 191
A30: 36733 | B30: 0.0030844907 | C30: 0.0030891204 | D30: 0.0033252315 | E30: 0.0033738426 | F30: 0.0033969907 | G30: 0.0034293981 | H30: 0.0010277778 | P30: =SUM(B30:O30) -> 0.020726852 | Q30: 6.35 | R30: =P30/Q30 -> 0.0032640712 | S30: 182 | T30: 172 | U30: 156 | V30: 171 | W30: 174 | X30: 174 | Y30: 175 | Z30: 174
A31: 36738 | B31: 0.0031041667 | C31: 0.0030381944 | D31: 0.003099537 | E31: 0.003125 | F31: 0.0032280093 | G31: 0.0029814815 | H31: 0.0010231481 | P31: =SUM(B31:O31) -> 0.019599537 | Q31: 6.35 | R31: =P31/Q31 -> 0.0030865413 | S31: 187 | T31: 173 | U31: 155 | V31: 169 | W31: 174 | X31: 176 | Y31: 177 | Z31: 183
A32: 36741 | B32: 0.0030671296 | C32: 0.002962963 | D32: 0.0031377315 | E32: 0.0032939815 | F32: 0.0033483796 | G32: 0.003099537 | H32: 0.0010416667 | P32: =SUM(B32:O32) -> 0.019951389 | Q32: 6.35 | R32: =P32/Q32 -> 0.003141951 | S32: 191 | T32: 175 | U32: 154 | V32: 173 | W32: 176 | X32: 177 | Y32: 178 | Z32: 185
A33: 36753 | B33: 0.0030081019 | C33: 0.0029988426 | D33: 0.0030231481 | E33: 0.0030451389 | F33: 0.0032013889 | G33: 0.0029039352 | H33: 0.00093634259 | P33: =SUM(B33:O33) -> 0.019116898 | Q33: 6.35 | R33: =P33/Q33 -> 0.0030105351 | S33: 192 | T33: 171 | U33: 149 | V33: 165 | W33: 171 | X33: 175 | Y33: 176 | Z33: 183
A34: 36763 | B34: 0.0030416667 | C34: 0.0030972222 | D34: 0.0033414352 | E34: 0.0032511574 | F34: 0.0033078704 | G34: 0.003125 | H34: 0.001005787 | P34: =SUM(B34:O34) -> 0.020170139 | Q34: 6.35 | R34: =P34/Q34 -> 0.0031763998 | S34: 196 | T34: 178 | U34: 156 | V34: 175 | W34: 177 | X34: 182 | Y34: 182 | Z34: 190
A35: 36767 | B35: 0.003005787 | C35: 0.0029328704 | D35: 0.0030868056 | E35: 0.0033159722 | F35: 0.0030636574 | G35: 0.0028240741 | H35: 0.00091666667 | P35: =SUM(B35:O35) -> 0.019145833 | Q35: 6.35 | R35: =P35/Q35 -> 0.0030150919 | S35: 195 | T35: 175 | U35: 155 | V35: 173 | W35: 175 | X35: 176 | Y35: 178 | Z35: 187
A36: 36774 | B36: 0.0030081019 | C36: 0.0029351852 | D36: 0.0029444444 | E36: 0.0029814815 | F36: 0.0030150463 | G36: 0.0028125 | H36: 0.00088657407 | P36: =SUM(B36:O36) -> 0.018583333 | Q36: 6.35 | R36: =P36/Q36 -> 0.0029265092 | S36: 193 | T36: 171 | U36: 149 | V36: 168 | W36: 172 | X36: 176 | Y36: 176 | Z36: 181
A37: 36777 | B37: 0.0028530093 | C37: 0.0027986111 | D37: 0.0029467593 | E37: 0.003068287 | F37: 0.0029918981 | G37: 0.0028564815 | H37: 0.00091087963 | P37: =SUM(B37:O37) -> 0.018425926 | Q37: 6.35 | R37: =P37/Q37 -> 0.0029017206 | S37: 196 | T37: 178 | U37: 151 | V37: 175 | W37: 179 | X37: 180 | Y37: 184 | Z37: 190
A38: 36780 | B38: 0.002931713 | C38: 0.0028425926 | D38: 0.0028842593 | E38: 0.0030196759 | F38: 0.0029259259 | G38: 0.0027974537 | H38: 0.00089467593 | P38: =SUM(B38:O38) -> 0.018296296 | Q38: 6.35 | R38: =P38/Q38 -> 0.0028813065 | S38: 191 | T38: 174 | U38: 149 | V38: 171 | W38: 176 | X38: 177 | Y38: 181 | Z38: 184
A39: 36783 | B39: 0.002818287 | C39: 0.0027893519 | D39: 0.0028460648 | E39: 0.0028125 | F39: 0.0028796296 | G39: 0.0027951389 | H39: 0.00088425926 | P39: =SUM(B39:O39) -> 0.017825231 | Q39: 6.35 | R39: =P39/Q39 -> 0.0028071231 | S39: 195 | T39: 176 | U39: 153 | V39: 172 | W39: 176 | X39: 181 | Y39: 183 | Z39: 187
A40: 36785 | B40: 0.0027604167 | C40: 0.0027928241 | D40: 0.0029456019 | E40: 0.0028969907 | F40: 0.0029039352 | G40: 0.002818287 | H40: 0.00090972222 | P40: =SUM(B40:O40) -> 0.018027778 | Q40: 6.35 | R40: =P40/Q40 -> 0.0028390201 | S40: 194 | T40: 179 | U40: 161 | V40: 177 | W40: 179 | X40: 182 | Y40: 185 | Z40: 188
...

Sheet Viad test
A1: RONDE 1 | B1: 0.001537037 | C1: 115
A2: RONDE 2 | B2: 0.0030648148 | C2: 117
A3: RONDE 3 | B3: 0.0046180556 | C3: 118 | D3: =Hartslagen!G3829 -> 116.4625
A4: Rust 1 | B4: 0.0053206019 | C4: 98 | D4: =MIN(Hartslagen!C3830:C3841) -> 75
A5: RONDE 1 | B5: 0.0067337963 | C5: 116
A6: RONDE 2 | B6: 0.0081689815 | C6: 122
A7: RONDE 3 | B7: 0.0095752315 | C7: 123 | D7: =Hartslagen!G3916 -> 119.85333
A8: Rust 2 | B8: 0.010186343 | C8: 100 | D8: 82
A9: RONDE 1 | B9: 0.011605324 | C9: 93 | D9: Niet gelopen
A10: RONDE 2 | B10: 0.012927083 | C10: 113
A11: RONDE 3 | B11: 0.01425463 | C11: 124
A12: Rust 3 | B12: 0.014951389 | C12: 96 | D12: 82
A13: RONDE1 | B13: 0.016210648 | C13: 118
A14: RONDE 2 | B14: 0.017428241 | C14: 130
A15: RONDE 3 | B15: 0.018670139 | C15: 130 | D15: =Hartslagen!G4072 -> 127.375
A16: Rust 4 | B16: 0.019363426 | C16: 111 | D16: 84
A17: RONDE 1 | B17: 0.02053588 | C17: 126
A18: RONDE 2 | B18: 0.021699074 | C18: 138
A19: RONDE 3 | B19: 0.022862269 | C19: 136 | D19: =Hartslagen!G4145 -> 133.91803
A20: Rust 5 | B20: 0.023555556 | C20: 113 | D20: 90
A21: RONDE 1 | B21: 0.02466088 | C21: 130
A22: RONDE 2 | B22: 0.025740741 | C22: 142
A23: RONDE 3 | B23: 0.026849537 | C23: 142 | D23: =Hartslagen!G4213 -> 138.625
A24: Rust 6 | B24: 0.0275625 | C24: 122 | D24: 89
A25: RONDE 1 | B25: 0.028599537 | C25: 138
A26: RONDE 2 | B26: 0.029638889 | C26: 148
A27: RONDE 3 | B27: 0.030673611 | C27: 148 | D27: =Hartslagen!G4280 -> 145.48148
A28: Rust 7 | B28: 0.031366898 | C28: 122 | D28: 94
A29: RONDE 1 | B29: 0.032361111 | C29: 135
A30: RONDE 2 | B30: ----
A31: RONDE 3 | B31: 0.034324074 | C31: 153 | D31: =Hartslagen!G4343 -> 148.31373
A32: Rust 8 | B32: 0.035018519 | C32: 131 | D32: 104
A33: RONDE 1 | B33: 0.035957176 | C33: 140
A34: RONDE 2 | B34: ----
A35: RONDE 3 | B35: 0.037831019 | C35: 157 | D35: =Hartslagen!G4403 -> 152.625
A36: Rust 9 | B36: 0.038527778 | C36: 137 | D36: 115
A37: RONDE 1 | B37: 0.039430556 | C37: 143
A38: RONDE 2 | B38: 0.040315972 | C38: 162
A39: RONDE 3 | B39: 0.041209491 | C39: 164 | D39: =Hartslagen!G4462 -> 156.82979
A40: Rust 10 | B40: 0.041898148 | C40: 139 | D40: 120
...

Sheet Viad
A1: Lopen in de corner driehoeken en voor de goalen
A4: 1 ronde | B4: =156*4+177*2 -> 978 | C4: voeten
A5: 1 voet | B5: 30 | C5: cm
A6: 978 voeten | B6: =B4*B5/100 -> 293.4 | C6: m
A7: 1 ronde | B7: =B6/1000 -> 0.2934 | C7: km | D7: =4*7*B7 -> 8.2152
A9: Van 1 tot 2 | B9: 156 | C9: voeten | D9: =$B$5*B9/100 -> 46.8 | E9: meter | O9: 8
A10: Van 2 tot 3 | B10: 156 | C10: voeten | D10: =$B$5*B10/100 -> 46.8 | E10: meter | O10: 8.625
A11: Van 3 to 4 | B11: 177 | C11: voeten | D11: =$B$5*B11/100 -> 53.1 | E11: meter | O11: 9.25
A12: Van 4 to 5 | B12: 156 | C12: voeten | D12: =$B$5*B12/100 -> 46.8 | E12: meter | O12: 9.875
A13: Van 5 tot 6 | B13: 156 | C13: voeten | D13: =$B$5*B13/100 -> 46.8 | E13: meter | O13: 10.5
A14: Van 6 tot 1 | B14: 177 | C14: voeten | D14: =$B$5*B14/100 -> 53.1 | E14: meter | O14: 11.125
O15: 11.75
O16: 12.375
O17: 13
O18: 13.625
A19: VIAD test | O19: 14.25
A21: over 4 ronden | B21: =4*B7 -> 1.1736 | C21: km | E21: tijden voor een bepaalde snelheid (km/u) | I21: Rust | J21: 0.00069444444
C22: tot voet | D22: meter | E22: 10 | F22: 10.35 | G22: 10.7 | H22: 11.05 | I22: 11.4 | J22: 11.75 | K22: 12.1 | L22: 12.45 | M22: 12.8 | N22: 13.15 | O22: 13.5
A23: Punt 1 | B23: 156 | C23: =B23 -> 156 | D23: =C23*30/100 -> 46.8 | E23: =($D23/(24*E$22))/1000 -> 0.000195 | F23: =($D23/(24*F$22))/1000 -> 0.0001884058 | G23: =($D23/(24*G$22))/1000 -> 0.00018224299 | H23: =($D23/(24*H$22))/1000 -> 0.00017647059 | I23: =($D23/(24*I$22))/1000 -> 0.00017105263 | J23: =($D23/(24*J$22))/1000 -> 0.00016595745 | K23: =($D23/(24*K$22))/1000 -> 0.00016115702 | L23: =($D23/(24*L$22))/1000 -> 0.00015662651 | ... O23: =($D23/(24*O$22))/1000 -> 0.00014444444
A24: Punt 2 | B24: 156 | C24: =C23+B24 -> 312 | D24: =C24*30/100 -> 93.6 | E24: =($D24/(24*E$22))/1000 -> 0.00039 | F24: =($D24/(24*F$22))/1000 -> 0.00037681159 | G24: =($D24/(24*G$22))/1000 -> 0.00036448598 | H24: =($D24/(24*H$22))/1000 -> 0.00035294118 | I24: =($D24/(24*I$22))/1000 -> 0.00034210526 | J24: =($D24/(24*J$22))/1000 -> 0.00033191489 | K24: =($D24/(24*K$22))/1000 -> 0.00032231405 | L24: =($D24/(24*L$22))/1000 -> 0.00031325301 | ... O24: =($D24/(24*O$22))/1000 -> 0.00028888889
A25: Punt 3 | B25: 177 | C25: =C24+B25 -> 489 | D25: =C25*30/100 -> 146.7 | E25: =($D25/(24*E$22))/1000 -> 0.00061125 | F25: =($D25/(24*F$22))/1000 -> 0.00059057971 | G25: =($D25/(24*G$22))/1000 -> 0.00057126168 | H25: =($D25/(24*H$22))/1000 -> 0.00055316742 | I25: =($D25/(24*I$22))/1000 -> 0.00053618421 | J25: =($D25/(24*J$22))/1000 -> 0.00052021277 | K25: =($D25/(24*K$22))/1000 -> 0.00050516529 | L25: =($D25/(24*L$22))/1000 -> 0.00049096386 | ... O25: =($D25/(24*O$22))/1000 -> 0.00045277778
A26: Punt 4 | B26: 156 | C26: =C25+B26 -> 645 | D26: =C26*30/100 -> 193.5 | E26: =($D26/(24*E$22))/1000 -> 0.00080625 | F26: =($D26/(24*F$22))/1000 -> 0.00077898551 | G26: =($D26/(24*G$22))/1000 -> 0.00075350467 | H26: =($D26/(24*H$22))/1000 -> 0.00072963801 | I26: =($D26/(24*I$22))/1000 -> 0.00070723684 | J26: =($D26/(24*J$22))/1000 -> 0.00068617021 | K26: =($D26/(24*K$22))/1000 -> 0.00066632231 | L26: =($D26/(24*L$22))/1000 -> 0.00064759036 | ... O26: =($D26/(24*O$22))/1000 -> 0.00059722222
A27: Punt 5 | B27: 156 | C27: =C26+B27 -> 801 | D27: =C27*30/100 -> 240.3 | E27: =($D27/(24*E$22))/1000 -> 0.00100125 | F27: =($D27/(24*F$22))/1000 -> 0.0009673913 | G27: =($D27/(24*G$22))/1000 -> 0.00093574766 | H27: =($D27/(24*H$22))/1000 -> 0.0009061086 | I27: =($D27/(24*I$22))/1000 -> 0.00087828947 | J27: =($D27/(24*J$22))/1000 -> 0.00085212766 | K27: =($D27/(24*K$22))/1000 -> 0.00082747934 | L27: =($D27/(24*L$22))/1000 -> 0.00080421687 | ... O27: =($D27/(24*O$22))/1000 -> 0.00074166667
A28: Punt 6 | B28: 177 | C28: =C27+B28 -> 978 | D28: =C28*30/100 -> 293.4 | E28: =($D28/(24*E$22))/1000 -> 0.0012225 | F28: =($D28/(24*F$22))/1000 -> 0.0011811594 | G28: =($D28/(24*G$22))/1000 -> 0.0011425234 | H28: =($D28/(24*H$22))/1000 -> 0.0011063348 | I28: =($D28/(24*I$22))/1000 -> 0.0010723684 | J28: =($D28/(24*J$22))/1000 -> 0.0010404255 | K28: =($D28/(24*K$22))/1000 -> 0.0010103306 | L28: =($D28/(24*L$22))/1000 -> 0.00098192771 | ... O28: =($D28/(24*O$22))/1000 -> 0.00090555556
A29: Punt 1 | B29: 156 | C29: =C28+B29 -> 1134 | D29: =C29*30/100 -> 340.2 | E29: =($D29/(24*E$22))/1000 -> 0.0014175 | F29: =($D29/(24*F$22))/1000 -> 0.0013695652 | G29: =($D29/(24*G$22))/1000 -> 0.0013247664 | H29: =($D29/(24*H$22))/1000 -> 0.0012828054 | I29: =($D29/(24*I$22))/1000 -> 0.0012434211 | J29: =($D29/(24*J$22))/1000 -> 0.001206383 | K29: =($D29/(24*K$22))/1000 -> 0.0011714876 | L29: =($D29/(24*L$22))/1000 -> 0.0011385542 | ... O29: =($D29/(24*O$22))/1000 -> 0.00105
A30: Punt 2 | B30: 156 | C30: =C29+B30 -> 1290 | D30: =C30*30/100 -> 387 | E30: =($D30/(24*E$22))/1000 -> 0.0016125 | F30: =($D30/(24*F$22))/1000 -> 0.001557971 | G30: =($D30/(24*G$22))/1000 -> 0.0015070093 | H30: =($D30/(24*H$22))/1000 -> 0.001459276 | I30: =($D30/(24*I$22))/1000 -> 0.0014144737 | J30: =($D30/(24*J$22))/1000 -> 0.0013723404 | K30: =($D30/(24*K$22))/1000 -> 0.0013326446 | L30: =($D30/(24*L$22))/1000 -> 0.0012951807 | ... O30: =($D30/(24*O$22))/1000 -> 0.0011944444
A31: Punt 3 | B31: 177 | C31: =C30+B31 -> 1467 | D31: =C31*30/100 -> 440.1 | E31: =($D31/(24*E$22))/1000 -> 0.00183375 | F31: =($D31/(24*F$22))/1000 -> 0.0017717391 | G31: =($D31/(24*G$22))/1000 -> 0.001713785 | H31: =($D31/(24*H$22))/1000 -> 0.0016595023 | I31: =($D31/(24*I$22))/1000 -> 0.0016085526 | J31: =($D31/(24*J$22))/1000 -> 0.0015606383 | K31: =($D31/(24*K$22))/1000 -> 0.0015154959 | L31: =($D31/(24*L$22))/1000 -> 0.0014728916 | ... O31: =($D31/(24*O$22))/1000 -> 0.0013583333
A32: Punt 4 | B32: 156 | C32: =C31+B32 -> 1623 | D32: =C32*30/100 -> 486.9 | E32: =($D32/(24*E$22))/1000 -> 0.00202875 | F32: =($D32/(24*F$22))/1000 -> 0.0019601449 | G32: =($D32/(24*G$22))/1000 -> 0.001896028 | H32: =($D32/(24*H$22))/1000 -> 0.0018359729 | I32: =($D32/(24*I$22))/1000 -> 0.0017796053 | J32: =($D32/(24*J$22))/1000 -> 0.0017265957 | K32: =($D32/(24*K$22))/1000 -> 0.0016766529 | L32: =($D32/(24*L$22))/1000 -> 0.0016295181 | ... O32: =($D32/(24*O$22))/1000 -> 0.0015027778
