Workbook

Sheet Berekeningen
A1: Rekeningen
A2: WAT | B2: KOSTEN | C2: WIE BETAALD
A3: CHINEES | B3: 350 | C3: Maria
A4: DRANK | B4: 180.5 | C4: Wim
A5: Biscuit | B5: 16.78 | C5: Benny
A6: Cava 4 flessen | B6: =7.99*4 -> 31.96 | C6: Lief VO
A7: chips | B7: =1.65+1.98+1.9 -> 5.53 | C7: Lief VO
A8: olijven+tomaat | B8: =2.59+2.59+2.59+2.99 -> 10.76 | C8: Lief VO
A9: houtmijt | B9: 15 | C9: Lucy
A10: houtmijt + tafelpapier | B10: =10+6 -> 16 | C10: Lief M
A11: zaal | B11: 50 | C11: Lief M
A12: Totaal | B12: =SUM(B3:B11) -> 676.53
A14: Wie heeft wat mee
A15: 5 flessen fris | B15: =1.52*5 -> 7.6 | C15: Noella
A16: drank | B16: =3.67*2+3.95+1.64 -> 12.93 | C16: Lucy
A17: drank | B17: =3.67*2 -> 7.34 | C17: Paula
A18: drank | B18: =3.95*4+1.28*3+0.57+1.64+1.57 -> 23.42 | C18: Lief M
A19: Leeggoed | B19: 13.5 | C19: Wim
A20: 6fl fanta | B20: =6*1.64 -> 9.84 | C20: Wim
A21: 6fl Cola + 6fl Light | B21: =12*1.52 -> 18.24 | C21: Wim
A22: Bier | B22: 9.54 | C22: Wim
A23: Smurfen Bubbels | B23: =2*1.85 -> 3.7 | C23: Wim
A24: totaal | B24: =SUM(B15:B23) -> 106.11
A26: Kosten | B26: =B12-B24 -> 570.42
A27: Aantal Personen | B27: =Personen!E48 -> 31
A28: Kosten per persoon | B28: =B26/B27 -> 18.400645
A30: WIM
A31: 3,5 personen | B31: =3.5*B28 -> 64.402258
A32: Rekening Drank | B32: =B4 -> 180.5
A33: Drank mee | B33: =SUM(B19:B23) -> 54.82
A34: totaal Wim | B34: =B31-B32+B33 -> -61.277742
A36: RINA
A37: 2 personen | B37: =2*B28 -> 36.80129
A38: totaal Rina | B38: =B37 -> 36.80129
A40: LIEF M
A41: 5,5 personen | B41: =5.5*B28 -> 101.20355
A42: Rekeningen | B42: =SUM(B10:B11) -> 66
A43: Drank mee | B43: =B18 -> 23.42
A44: totaal Lieve M | B44: =B41-B42+B43 -> 58.623548
A46: LIEF VO
...

Sheet Personen
A1: NAAM | B1: KOMT/KOMT NIET | C1: VOLW/KIND | D1: OPMERKING
A2: WIM | B2: OK | C2: VOLW | E2: 1
A3: SENDY | B3: OK | C3: VOLW | E3: 1
A4: ARNE | B4: OK | C4: KIND | D4: TIBO EN ARNE SAMEN 1 VOLW | E4: 0.5
A5: TIBO | B5: OK | C5: KIND | E5: 0.5
A6: LOTTe | B6: OK | C6: KIND | E6: 0.5
A8: TANTE RINA | B8: OK | C8: VOLW | E8: 1
A9: NONKEL LOUIS | B9: OK | C9: VOLW | E9: 1
A11: LIEF | B11: OK | C11: VOLW | D11: KOMT NA PETER PAN | E11: 1
A12: HERMAN | B12: OK | C12: VOLW | E12: 1
A13: JORIEN | B13: OK | C13: KIND | D13: KOMT NA PETER PAN | E13: 0.5
A14: LIEN | B14: OK | C14: VOLW | D14: KOMT NA PETER PAN | E14: 1
A15: LAURENS | B15: OK | C15: VOLW | D15: KOMT NA PETER PAN | E15: 1
A16: TOON | B16: OK | C16: VOLW | E16: 1
A18: TONNY | B18: OK | C18: VOLW | D18: KOMT NA HET WERK, 17.00 | E18: 1
A19: LIEF | B19: OK | C19: VOLW | E19: 1
A20: COR | B20: OK | C20: KIND | E20: 0.5
A22: NOELLA | B22: OK | C22: VOLW | E22: 1
A23: GEERT | B23: OK | C23: VOLW | E23: 1
A24: GIEL | B24: OK | C24: VOLW | E24: 1
A25: MICHELLE | B25: OK | C25: VOLW | E25: 1
A26: BRENT | B26: OK | C26: VOLW | E26: 1
A28: OMA | B28: OK | C28: VOLW | E28: 1
A30: LUCY | B30: OK | C30: VOLW | D30: KOMT NA PETER PAN | E30: 1
A31: BOB | B31: OK | C31: VOLW | E31: 1
A32: VALERIE | B32: OK | C32: VOLW | D32: KOMT NA PETER PAN | E32: 1
A34: BENNY | B34: OK | C34: VOLW | E34: 1
A35: SUZANNE | B35: OK | C35: VOLW | E35: 1
A36: ANDRES | B36: OK | C36: KIND | E36: 0.5
A38: NONKEL LUCIEN | B38: OK | C38: VOLW | E38: 1
A39: TANTE PAULA | B39: OK | C39: VOLW | E39: 1
A41: WENDY | B41: OK | C41: VOLW | E41: 1
A42: KOEN | B42: OK | C42: VOLW | E42: 1
A43: ALIX | B43: OK | C43: KIND | E43: 0.5
A44: ANAÏS | B44: OK | C44: KIND | E44: 0.5
A46: TANTE MIRIAM | B46: OK | C46: VOLW | E46: 1
A48: Aantal personen | E48: =SUM(E2:E46) -> 31
C49: 28 VOLW
C50: 5 KIND

Sheet OVERZICHT
A1: OVERZICHT
A2: (positief=te betalen, negatief=te ontvangen)
A4: Wim | B4: =Berekeningen!B34 -> -61.277742
A5: Rina | B5: =Berekeningen!B38 -> 36.80129 | C5: 40
A6: Lief M | B6: =Berekeningen!B44 -> 58.623548
A7: Lief VO | B7: =Berekeningen!B49 -> -2.2483871
A8: Noella | B8: =Berekeningen!B54 -> 99.603226
A9: Maria | B9: =Berekeningen!B59 -> -331.59935
A10: Lucy | B10: =Berekeningen!B65 -> 53.131935
A11: Benny | B11: =Berekeningen!B70 -> 29.221613
A12: Paula | B12: =Berekeningen!B75 -> 44.14129
A13: Wendy | B13: =Berekeningen!B79 -> 55.201935
A14: Miriam | B14: =Berekeningen!B83 -> 18.400645

Sheet OMA
A3: LIEF
A4: betalen/ontvangen | B4: =OVERZICHT!B7 -> -2.2483871
A5: 2,5 personen | B5: =Berekeningen!B47 -> 46.001613
A6: Totaal | B6: =B4-B5 -> -48.25
A8: NOELLA
A9: betalen ontvangen | B9: =OVERZICHT!B8 -> 99.603226
A10: 5 personen | B10: =Berekeningen!B52 -> 92.003226
A11: Totaal | B11: =B9-B10 -> 7.6
A14: OMA
A15: betalen ontvangen | B15: =OVERZICHT!B9 -> -331.59935
A16: 7,5 personen | B16: =B5+B10 -> 138.00484
A17: Totaal | B17: =B15+B16 -> -193.59452 | C17: 200
